[2025-03-24T17:18:40.387+0000] {local_task_job_runner.py:123} INFO - ::group::Pre task execution logs
[2025-03-24T17:18:40.395+0000] {taskinstance.py:2614} INFO - Dependencies all met for dep_context=non-requeueable deps ti=<TaskInstance: e2e_data_pipeline.dbt_execute manual__2025-03-24T16:17:51.573790+00:00 [queued]>
[2025-03-24T17:18:40.398+0000] {taskinstance.py:2614} INFO - Dependencies all met for dep_context=requeueable deps ti=<TaskInstance: e2e_data_pipeline.dbt_execute manual__2025-03-24T16:17:51.573790+00:00 [queued]>
[2025-03-24T17:18:40.398+0000] {taskinstance.py:2867} INFO - Starting attempt 12 of 12
[2025-03-24T17:18:40.402+0000] {taskinstance.py:2890} INFO - Executing <Task(BashOperator): dbt_execute> on 2025-03-24 16:17:51.573790+00:00
[2025-03-24T17:18:40.406+0000] {standard_task_runner.py:104} INFO - Running: ['airflow', 'tasks', 'run', 'e2e_data_pipeline', 'dbt_execute', 'manual__2025-03-24T16:17:51.573790+00:00', '--job-id', '28', '--raw', '--subdir', 'DAGS_FOLDER/data_pipeline.py', '--cfg-path', '/tmp/tmpox9ctg3y']
[2025-03-24T17:18:40.407+0000] {logging_mixin.py:190} WARNING - /home/airflow/.local/lib/python3.12/site-packages/airflow/task/task_runner/standard_task_runner.py:70 DeprecationWarning: This process (pid=963) is multi-threaded, use of fork() may lead to deadlocks in the child.
[2025-03-24T17:18:40.407+0000] {standard_task_runner.py:72} INFO - Started process 964 to run task
[2025-03-24T17:18:40.407+0000] {standard_task_runner.py:105} INFO - Job 28: Subtask dbt_execute
[2025-03-24T17:18:40.427+0000] {task_command.py:467} INFO - Running <TaskInstance: e2e_data_pipeline.dbt_execute manual__2025-03-24T16:17:51.573790+00:00 [running]> on host 5534f92a2ac4
[2025-03-24T17:18:40.455+0000] {taskinstance.py:3134} INFO - Exporting env vars: AIRFLOW_CTX_DAG_OWNER='airflow' AIRFLOW_CTX_DAG_ID='e2e_data_pipeline' AIRFLOW_CTX_TASK_ID='dbt_execute' AIRFLOW_CTX_EXECUTION_DATE='2025-03-24T16:17:51.573790+00:00' AIRFLOW_CTX_TRY_NUMBER='12' AIRFLOW_CTX_DAG_RUN_ID='manual__2025-03-24T16:17:51.573790+00:00'
[2025-03-24T17:18:40.455+0000] {taskinstance.py:732} INFO - ::endgroup::
[2025-03-24T17:18:40.460+0000] {subprocess.py:78} INFO - Tmp dir root location: /tmp
[2025-03-24T17:18:40.460+0000] {subprocess.py:88} INFO - Running command: ['/usr/bin/bash', '-c', 'docker exec data_pipeline-dbt-1 dbt test --fail-fast && dbt run']
[2025-03-24T17:18:40.464+0000] {subprocess.py:99} INFO - Output:
[2025-03-24T17:18:41.462+0000] {subprocess.py:106} INFO - [0m17:18:41  Running with dbt=1.9.0
[2025-03-24T17:18:41.629+0000] {subprocess.py:106} INFO - [0m17:18:41  Registered adapter: postgres=1.9.0
[2025-03-24T17:18:42.275+0000] {subprocess.py:106} INFO - [0m17:18:42  Found 3 models, 3 data tests, 1 source, 430 macros
[2025-03-24T17:18:42.277+0000] {subprocess.py:106} INFO - [0m17:18:42
[2025-03-24T17:18:42.278+0000] {subprocess.py:106} INFO - [0m17:18:42  Concurrency: 1 threads (target='dev')
[2025-03-24T17:18:42.279+0000] {subprocess.py:106} INFO - [0m17:18:42
[2025-03-24T17:18:42.385+0000] {subprocess.py:106} INFO - [0m17:18:42  1 of 3 START test source_not_null_public_premier_league_2425_raw_away_team ..... [RUN]
[2025-03-24T17:18:42.422+0000] {subprocess.py:106} INFO - [0m17:18:42  1 of 3 PASS source_not_null_public_premier_league_2425_raw_away_team ........... [[32mPASS[0m in 0.04s]
[2025-03-24T17:18:42.423+0000] {subprocess.py:106} INFO - [0m17:18:42  2 of 3 START test source_not_null_public_premier_league_2425_raw_home_team ..... [RUN]
[2025-03-24T17:18:42.440+0000] {subprocess.py:106} INFO - [0m17:18:42  2 of 3 PASS source_not_null_public_premier_league_2425_raw_home_team ........... [[32mPASS[0m in 0.02s]
[2025-03-24T17:18:42.441+0000] {subprocess.py:106} INFO - [0m17:18:42  3 of 3 START test source_not_null_public_premier_league_2425_raw_matchday ...... [RUN]
[2025-03-24T17:18:42.456+0000] {subprocess.py:106} INFO - [0m17:18:42  3 of 3 PASS source_not_null_public_premier_league_2425_raw_matchday ............ [[32mPASS[0m in 0.01s]
[2025-03-24T17:18:42.467+0000] {subprocess.py:106} INFO - [0m17:18:42
[2025-03-24T17:18:42.467+0000] {subprocess.py:106} INFO - [0m17:18:42  Finished running 3 data tests in 0 hours 0 minutes and 0.19 seconds (0.19s).
[2025-03-24T17:18:42.493+0000] {subprocess.py:106} INFO - [0m17:18:42
[2025-03-24T17:18:42.493+0000] {subprocess.py:106} INFO - [0m17:18:42  [32mCompleted successfully[0m
[2025-03-24T17:18:42.494+0000] {subprocess.py:106} INFO - [0m17:18:42
[2025-03-24T17:18:42.494+0000] {subprocess.py:106} INFO - [0m17:18:42  Done. PASS=3 WARN=0 ERROR=0 SKIP=0 TOTAL=3
[2025-03-24T17:18:43.662+0000] {subprocess.py:106} INFO - /usr/bin/bash: line 1: dbt: command not found
[2025-03-24T17:18:43.663+0000] {subprocess.py:110} INFO - Command exited with return code 127
[2025-03-24T17:18:43.667+0000] {taskinstance.py:3313} ERROR - Task failed with exception
Traceback (most recent call last):
  File "/home/airflow/.local/lib/python3.12/site-packages/airflow/models/taskinstance.py", line 768, in _execute_task
    result = _execute_callable(context=context, **execute_callable_kwargs)
             ^^^^^^^^^^^^^^^^^^^^^^^^^^^^^^^^^^^^^^^^^^^^^^^^^^^^^^^^^^^^^
  File "/home/airflow/.local/lib/python3.12/site-packages/airflow/models/taskinstance.py", line 734, in _execute_callable
    return ExecutionCallableRunner(
           ^^^^^^^^^^^^^^^^^^^^^^^^
  File "/home/airflow/.local/lib/python3.12/site-packages/airflow/utils/operator_helpers.py", line 252, in run
    return self.func(*args, **kwargs)
           ^^^^^^^^^^^^^^^^^^^^^^^^^^
  File "/home/airflow/.local/lib/python3.12/site-packages/airflow/models/baseoperator.py", line 424, in wrapper
    return func(self, *args, **kwargs)
           ^^^^^^^^^^^^^^^^^^^^^^^^^^^
  File "/home/airflow/.local/lib/python3.12/site-packages/airflow/operators/bash.py", line 276, in execute
    raise AirflowException(
airflow.exceptions.AirflowException: Bash command failed. The command returned a non-zero exit code 127.
[2025-03-24T17:18:43.669+0000] {taskinstance.py:1226} INFO - Marking task as FAILED. dag_id=e2e_data_pipeline, task_id=dbt_execute, run_id=manual__2025-03-24T16:17:51.573790+00:00, execution_date=20250324T161751, start_date=20250324T171840, end_date=20250324T171843
[2025-03-24T17:18:43.679+0000] {taskinstance.py:341} INFO - ::group::Post task execution logs
[2025-03-24T17:18:43.679+0000] {standard_task_runner.py:124} ERROR - Failed to execute job 28 for task dbt_execute (Bash command failed. The command returned a non-zero exit code 127.; 964)
Traceback (most recent call last):
  File "/home/airflow/.local/lib/python3.12/site-packages/airflow/task/task_runner/standard_task_runner.py", line 117, in _start_by_fork
    ret = args.func(args, dag=self.dag)
          ^^^^^^^^^^^^^^^^^^^^^^^^^^^^^
  File "/home/airflow/.local/lib/python3.12/site-packages/airflow/cli/cli_config.py", line 49, in command
    return func(*args, **kwargs)
           ^^^^^^^^^^^^^^^^^^^^^
  File "/home/airflow/.local/lib/python3.12/site-packages/airflow/utils/cli.py", line 116, in wrapper
    return f(*args, **kwargs)
           ^^^^^^^^^^^^^^^^^^
  File "/home/airflow/.local/lib/python3.12/site-packages/airflow/cli/commands/task_command.py", line 483, in task_run
    task_return_code = _run_task_by_selected_method(args, _dag, ti)
                       ^^^^^^^^^^^^^^^^^^^^^^^^^^^^^^^^^^^^^^^^^^^^
  File "/home/airflow/.local/lib/python3.12/site-packages/airflow/cli/commands/task_command.py", line 256, in _run_task_by_selected_method
    return _run_raw_task(args, ti)
           ^^^^^^^^^^^^^^^^^^^^^^^
  File "/home/airflow/.local/lib/python3.12/site-packages/airflow/cli/commands/task_command.py", line 341, in _run_raw_task
    return ti._run_raw_task(
           ^^^^^^^^^^^^^^^^^
  File "/home/airflow/.local/lib/python3.12/site-packages/airflow/utils/session.py", line 97, in wrapper
    return func(*args, session=session, **kwargs)
           ^^^^^^^^^^^^^^^^^^^^^^^^^^^^^^^^^^^^^^
  File "/home/airflow/.local/lib/python3.12/site-packages/airflow/models/taskinstance.py", line 3006, in _run_raw_task
    return _run_raw_task(
           ^^^^^^^^^^^^^^
  File "/home/airflow/.local/lib/python3.12/site-packages/airflow/models/taskinstance.py", line 274, in _run_raw_task
    TaskInstance._execute_task_with_callbacks(
  File "/home/airflow/.local/lib/python3.12/site-packages/airflow/models/taskinstance.py", line 3161, in _execute_task_with_callbacks
    result = self._execute_task(context, task_orig)
             ^^^^^^^^^^^^^^^^^^^^^^^^^^^^^^^^^^^^^^
  File "/home/airflow/.local/lib/python3.12/site-packages/airflow/models/taskinstance.py", line 3185, in _execute_task
    return _execute_task(self, context, task_orig)
           ^^^^^^^^^^^^^^^^^^^^^^^^^^^^^^^^^^^^^^^
  File "/home/airflow/.local/lib/python3.12/site-packages/airflow/models/taskinstance.py", line 768, in _execute_task
    result = _execute_callable(context=context, **execute_callable_kwargs)
             ^^^^^^^^^^^^^^^^^^^^^^^^^^^^^^^^^^^^^^^^^^^^^^^^^^^^^^^^^^^^^
  File "/home/airflow/.local/lib/python3.12/site-packages/airflow/models/taskinstance.py", line 734, in _execute_callable
    return ExecutionCallableRunner(
           ^^^^^^^^^^^^^^^^^^^^^^^^
  File "/home/airflow/.local/lib/python3.12/site-packages/airflow/utils/operator_helpers.py", line 252, in run
    return self.func(*args, **kwargs)
           ^^^^^^^^^^^^^^^^^^^^^^^^^^
  File "/home/airflow/.local/lib/python3.12/site-packages/airflow/models/baseoperator.py", line 424, in wrapper
    return func(self, *args, **kwargs)
           ^^^^^^^^^^^^^^^^^^^^^^^^^^^
  File "/home/airflow/.local/lib/python3.12/site-packages/airflow/operators/bash.py", line 276, in execute
    raise AirflowException(
airflow.exceptions.AirflowException: Bash command failed. The command returned a non-zero exit code 127.
[2025-03-24T17:18:43.724+0000] {local_task_job_runner.py:266} INFO - Task exited with return code 1
[2025-03-24T17:18:43.732+0000] {taskinstance.py:3901} INFO - 0 downstream tasks scheduled from follow-on schedule check
[2025-03-24T17:18:43.732+0000] {local_task_job_runner.py:245} INFO - ::endgroup::
