[2025-03-24T16:21:40.758+0000] {local_task_job_runner.py:123} INFO - ::group::Pre task execution logs
[2025-03-24T16:21:40.766+0000] {taskinstance.py:2614} INFO - Dependencies all met for dep_context=non-requeueable deps ti=<TaskInstance: e2e_data_pipeline.dbt_execute manual__2025-03-24T16:17:51.573790+00:00 [queued]>
[2025-03-24T16:21:40.770+0000] {taskinstance.py:2614} INFO - Dependencies all met for dep_context=requeueable deps ti=<TaskInstance: e2e_data_pipeline.dbt_execute manual__2025-03-24T16:17:51.573790+00:00 [queued]>
[2025-03-24T16:21:40.770+0000] {taskinstance.py:2867} INFO - Starting attempt 4 of 4
[2025-03-24T16:21:40.774+0000] {taskinstance.py:2890} INFO - Executing <Task(BashOperator): dbt_execute> on 2025-03-24 16:17:51.573790+00:00
[2025-03-24T16:21:40.778+0000] {logging_mixin.py:190} WARNING - /home/airflow/.local/lib/python3.12/site-packages/airflow/task/task_runner/standard_task_runner.py:70 DeprecationWarning: This process (pid=292) is multi-threaded, use of fork() may lead to deadlocks in the child.
[2025-03-24T16:21:40.777+0000] {standard_task_runner.py:104} INFO - Running: ['airflow', 'tasks', 'run', 'e2e_data_pipeline', 'dbt_execute', 'manual__2025-03-24T16:17:51.573790+00:00', '--job-id', '20', '--raw', '--subdir', 'DAGS_FOLDER/data_pipeline.py', '--cfg-path', '/tmp/tmp5bsqwl1h']
[2025-03-24T16:21:40.778+0000] {standard_task_runner.py:105} INFO - Job 20: Subtask dbt_execute
[2025-03-24T16:21:40.778+0000] {standard_task_runner.py:72} INFO - Started process 293 to run task
[2025-03-24T16:21:40.800+0000] {task_command.py:467} INFO - Running <TaskInstance: e2e_data_pipeline.dbt_execute manual__2025-03-24T16:17:51.573790+00:00 [running]> on host 5534f92a2ac4
[2025-03-24T16:21:40.831+0000] {taskinstance.py:3134} INFO - Exporting env vars: AIRFLOW_CTX_DAG_OWNER='airflow' AIRFLOW_CTX_DAG_ID='e2e_data_pipeline' AIRFLOW_CTX_TASK_ID='dbt_execute' AIRFLOW_CTX_EXECUTION_DATE='2025-03-24T16:17:51.573790+00:00' AIRFLOW_CTX_TRY_NUMBER='4' AIRFLOW_CTX_DAG_RUN_ID='manual__2025-03-24T16:17:51.573790+00:00'
[2025-03-24T16:21:40.832+0000] {taskinstance.py:732} INFO - ::endgroup::
[2025-03-24T16:21:40.836+0000] {subprocess.py:78} INFO - Tmp dir root location: /tmp
[2025-03-24T16:21:40.836+0000] {subprocess.py:88} INFO - Running command: ['/usr/bin/bash', '-c', 'docker exec data_pipeline-dbt-1 dbt test --fail-fast && dbt run']
[2025-03-24T16:21:40.839+0000] {subprocess.py:99} INFO - Output:
[2025-03-24T16:21:41.688+0000] {subprocess.py:106} INFO - [0m16:21:41  Running with dbt=1.9.0
[2025-03-24T16:21:41.692+0000] {subprocess.py:106} INFO - [0m16:21:41  Encountered an error:
[2025-03-24T16:21:41.692+0000] {subprocess.py:106} INFO - Runtime Error
[2025-03-24T16:21:41.692+0000] {subprocess.py:106} INFO - 
[2025-03-24T16:21:41.692+0000] {subprocess.py:106} INFO -   dbt encountered an error while trying to read your profiles.yml file.
[2025-03-24T16:21:41.692+0000] {subprocess.py:106} INFO - 
[2025-03-24T16:21:41.692+0000] {subprocess.py:106} INFO -   Runtime Error
[2025-03-24T16:21:41.692+0000] {subprocess.py:106} INFO -     Syntax error near line 9
[2025-03-24T16:21:41.693+0000] {subprocess.py:106} INFO -     ------------------------------
[2025-03-24T16:21:41.693+0000] {subprocess.py:106} INFO -     6  |       host: "{{ env_var('POSTGRES_HOST')}}"
[2025-03-24T16:21:41.693+0000] {subprocess.py:106} INFO -     7  |       user: "{{ env_var('POSTGRES_USER')}}"
[2025-03-24T16:21:41.693+0000] {subprocess.py:106} INFO -     8  |       password: "{{ env_var('POSTGRES_PASSWORD')}}"
[2025-03-24T16:21:41.693+0000] {subprocess.py:106} INFO -     9  |       port: {{ env_var('POSTGRES_PORT')}}
[2025-03-24T16:21:41.693+0000] {subprocess.py:106} INFO -     10 |       dbname: "{{ env_var('POSTGRES_DB')}}"
[2025-03-24T16:21:41.693+0000] {subprocess.py:106} INFO -     11 |       schema: public
[2025-03-24T16:21:41.693+0000] {subprocess.py:106} INFO - 
[2025-03-24T16:21:41.693+0000] {subprocess.py:106} INFO -     Raw Error:
[2025-03-24T16:21:41.693+0000] {subprocess.py:106} INFO -     ------------------------------
[2025-03-24T16:21:41.693+0000] {subprocess.py:106} INFO -     while constructing a mapping
[2025-03-24T16:21:41.694+0000] {subprocess.py:106} INFO -       in "<unicode string>", line 9, column 13
[2025-03-24T16:21:41.694+0000] {subprocess.py:106} INFO -     found unhashable key
[2025-03-24T16:21:41.694+0000] {subprocess.py:106} INFO -       in "<unicode string>", line 9, column 14
[2025-03-24T16:21:41.694+0000] {subprocess.py:106} INFO - 
[2025-03-24T16:21:42.935+0000] {subprocess.py:110} INFO - Command exited with return code 2
[2025-03-24T16:21:42.940+0000] {taskinstance.py:3313} ERROR - Task failed with exception
Traceback (most recent call last):
  File "/home/airflow/.local/lib/python3.12/site-packages/airflow/models/taskinstance.py", line 768, in _execute_task
    result = _execute_callable(context=context, **execute_callable_kwargs)
             ^^^^^^^^^^^^^^^^^^^^^^^^^^^^^^^^^^^^^^^^^^^^^^^^^^^^^^^^^^^^^
  File "/home/airflow/.local/lib/python3.12/site-packages/airflow/models/taskinstance.py", line 734, in _execute_callable
    return ExecutionCallableRunner(
           ^^^^^^^^^^^^^^^^^^^^^^^^
  File "/home/airflow/.local/lib/python3.12/site-packages/airflow/utils/operator_helpers.py", line 252, in run
    return self.func(*args, **kwargs)
           ^^^^^^^^^^^^^^^^^^^^^^^^^^
  File "/home/airflow/.local/lib/python3.12/site-packages/airflow/models/baseoperator.py", line 424, in wrapper
    return func(self, *args, **kwargs)
           ^^^^^^^^^^^^^^^^^^^^^^^^^^^
  File "/home/airflow/.local/lib/python3.12/site-packages/airflow/operators/bash.py", line 276, in execute
    raise AirflowException(
airflow.exceptions.AirflowException: Bash command failed. The command returned a non-zero exit code 2.
[2025-03-24T16:21:42.941+0000] {taskinstance.py:1226} INFO - Marking task as FAILED. dag_id=e2e_data_pipeline, task_id=dbt_execute, run_id=manual__2025-03-24T16:17:51.573790+00:00, execution_date=20250324T161751, start_date=20250324T162140, end_date=20250324T162142
[2025-03-24T16:21:42.950+0000] {taskinstance.py:341} INFO - ::group::Post task execution logs
[2025-03-24T16:21:42.951+0000] {standard_task_runner.py:124} ERROR - Failed to execute job 20 for task dbt_execute (Bash command failed. The command returned a non-zero exit code 2.; 293)
Traceback (most recent call last):
  File "/home/airflow/.local/lib/python3.12/site-packages/airflow/task/task_runner/standard_task_runner.py", line 117, in _start_by_fork
    ret = args.func(args, dag=self.dag)
          ^^^^^^^^^^^^^^^^^^^^^^^^^^^^^
  File "/home/airflow/.local/lib/python3.12/site-packages/airflow/cli/cli_config.py", line 49, in command
    return func(*args, **kwargs)
           ^^^^^^^^^^^^^^^^^^^^^
  File "/home/airflow/.local/lib/python3.12/site-packages/airflow/utils/cli.py", line 116, in wrapper
    return f(*args, **kwargs)
           ^^^^^^^^^^^^^^^^^^
  File "/home/airflow/.local/lib/python3.12/site-packages/airflow/cli/commands/task_command.py", line 483, in task_run
    task_return_code = _run_task_by_selected_method(args, _dag, ti)
                       ^^^^^^^^^^^^^^^^^^^^^^^^^^^^^^^^^^^^^^^^^^^^
  File "/home/airflow/.local/lib/python3.12/site-packages/airflow/cli/commands/task_command.py", line 256, in _run_task_by_selected_method
    return _run_raw_task(args, ti)
           ^^^^^^^^^^^^^^^^^^^^^^^
  File "/home/airflow/.local/lib/python3.12/site-packages/airflow/cli/commands/task_command.py", line 341, in _run_raw_task
    return ti._run_raw_task(
           ^^^^^^^^^^^^^^^^^
  File "/home/airflow/.local/lib/python3.12/site-packages/airflow/utils/session.py", line 97, in wrapper
    return func(*args, session=session, **kwargs)
           ^^^^^^^^^^^^^^^^^^^^^^^^^^^^^^^^^^^^^^
  File "/home/airflow/.local/lib/python3.12/site-packages/airflow/models/taskinstance.py", line 3006, in _run_raw_task
    return _run_raw_task(
           ^^^^^^^^^^^^^^
  File "/home/airflow/.local/lib/python3.12/site-packages/airflow/models/taskinstance.py", line 274, in _run_raw_task
    TaskInstance._execute_task_with_callbacks(
  File "/home/airflow/.local/lib/python3.12/site-packages/airflow/models/taskinstance.py", line 3161, in _execute_task_with_callbacks
    result = self._execute_task(context, task_orig)
             ^^^^^^^^^^^^^^^^^^^^^^^^^^^^^^^^^^^^^^
  File "/home/airflow/.local/lib/python3.12/site-packages/airflow/models/taskinstance.py", line 3185, in _execute_task
    return _execute_task(self, context, task_orig)
           ^^^^^^^^^^^^^^^^^^^^^^^^^^^^^^^^^^^^^^^
  File "/home/airflow/.local/lib/python3.12/site-packages/airflow/models/taskinstance.py", line 768, in _execute_task
    result = _execute_callable(context=context, **execute_callable_kwargs)
             ^^^^^^^^^^^^^^^^^^^^^^^^^^^^^^^^^^^^^^^^^^^^^^^^^^^^^^^^^^^^^
  File "/home/airflow/.local/lib/python3.12/site-packages/airflow/models/taskinstance.py", line 734, in _execute_callable
    return ExecutionCallableRunner(
           ^^^^^^^^^^^^^^^^^^^^^^^^
  File "/home/airflow/.local/lib/python3.12/site-packages/airflow/utils/operator_helpers.py", line 252, in run
    return self.func(*args, **kwargs)
           ^^^^^^^^^^^^^^^^^^^^^^^^^^
  File "/home/airflow/.local/lib/python3.12/site-packages/airflow/models/baseoperator.py", line 424, in wrapper
    return func(self, *args, **kwargs)
           ^^^^^^^^^^^^^^^^^^^^^^^^^^^
  File "/home/airflow/.local/lib/python3.12/site-packages/airflow/operators/bash.py", line 276, in execute
    raise AirflowException(
airflow.exceptions.AirflowException: Bash command failed. The command returned a non-zero exit code 2.
[2025-03-24T16:21:42.973+0000] {local_task_job_runner.py:266} INFO - Task exited with return code 1
[2025-03-24T16:21:42.979+0000] {taskinstance.py:3901} INFO - 0 downstream tasks scheduled from follow-on schedule check
[2025-03-24T16:21:42.980+0000] {local_task_job_runner.py:245} INFO - ::endgroup::
