[2025-03-24T17:10:13.597+0000] {local_task_job_runner.py:123} INFO - ::group::Pre task execution logs
[2025-03-24T17:10:13.604+0000] {taskinstance.py:2614} INFO - Dependencies all met for dep_context=non-requeueable deps ti=<TaskInstance: e2e_data_pipeline.dbt_execute manual__2025-03-24T16:17:51.573790+00:00 [queued]>
[2025-03-24T17:10:13.607+0000] {taskinstance.py:2614} INFO - Dependencies all met for dep_context=requeueable deps ti=<TaskInstance: e2e_data_pipeline.dbt_execute manual__2025-03-24T16:17:51.573790+00:00 [queued]>
[2025-03-24T17:10:13.607+0000] {taskinstance.py:2867} INFO - Starting attempt 8 of 8
[2025-03-24T17:10:13.611+0000] {taskinstance.py:2890} INFO - Executing <Task(BashOperator): dbt_execute> on 2025-03-24 16:17:51.573790+00:00
[2025-03-24T17:10:13.615+0000] {logging_mixin.py:190} WARNING - /home/airflow/.local/lib/python3.12/site-packages/airflow/task/task_runner/standard_task_runner.py:70 DeprecationWarning: This process (pid=828) is multi-threaded, use of fork() may lead to deadlocks in the child.
[2025-03-24T17:10:13.614+0000] {standard_task_runner.py:104} INFO - Running: ['airflow', 'tasks', 'run', 'e2e_data_pipeline', 'dbt_execute', 'manual__2025-03-24T16:17:51.573790+00:00', '--job-id', '24', '--raw', '--subdir', 'DAGS_FOLDER/data_pipeline.py', '--cfg-path', '/tmp/tmpdp747fyt']
[2025-03-24T17:10:13.616+0000] {standard_task_runner.py:105} INFO - Job 24: Subtask dbt_execute
[2025-03-24T17:10:13.616+0000] {standard_task_runner.py:72} INFO - Started process 829 to run task
[2025-03-24T17:10:13.633+0000] {task_command.py:467} INFO - Running <TaskInstance: e2e_data_pipeline.dbt_execute manual__2025-03-24T16:17:51.573790+00:00 [running]> on host 5534f92a2ac4
[2025-03-24T17:10:13.658+0000] {taskinstance.py:3134} INFO - Exporting env vars: AIRFLOW_CTX_DAG_OWNER='airflow' AIRFLOW_CTX_DAG_ID='e2e_data_pipeline' AIRFLOW_CTX_TASK_ID='dbt_execute' AIRFLOW_CTX_EXECUTION_DATE='2025-03-24T16:17:51.573790+00:00' AIRFLOW_CTX_TRY_NUMBER='8' AIRFLOW_CTX_DAG_RUN_ID='manual__2025-03-24T16:17:51.573790+00:00'
[2025-03-24T17:10:13.658+0000] {taskinstance.py:732} INFO - ::endgroup::
[2025-03-24T17:10:13.663+0000] {subprocess.py:78} INFO - Tmp dir root location: /tmp
[2025-03-24T17:10:13.663+0000] {subprocess.py:88} INFO - Running command: ['/usr/bin/bash', '-c', 'docker exec data_pipeline-dbt-1 dbt test --fail-fast && dbt run']
[2025-03-24T17:10:13.666+0000] {subprocess.py:99} INFO - Output:
[2025-03-24T17:10:14.544+0000] {subprocess.py:106} INFO - [0m17:10:14  Running with dbt=1.9.0
[2025-03-24T17:10:14.695+0000] {subprocess.py:106} INFO - [0m17:10:14  Registered adapter: postgres=1.9.0
[2025-03-24T17:10:14.985+0000] {subprocess.py:106} INFO - [0m17:10:14  Found 3 models, 4 data tests, 1 source, 430 macros
[2025-03-24T17:10:14.987+0000] {subprocess.py:106} INFO - [0m17:10:14
[2025-03-24T17:10:14.987+0000] {subprocess.py:106} INFO - [0m17:10:14  Concurrency: 1 threads (target='dev')
[2025-03-24T17:10:14.988+0000] {subprocess.py:106} INFO - [0m17:10:14
[2025-03-24T17:10:15.086+0000] {subprocess.py:106} INFO - [0m17:10:15  1 of 4 START test source_custom_score_format_public_premier_league_2425_raw_ ... [RUN]
[2025-03-24T17:10:15.118+0000] {subprocess.py:106} INFO - [0m17:10:15  1 of 4 ERROR source_custom_score_format_public_premier_league_2425_raw_ ........ [[31mERROR[0m in 0.03s]
[2025-03-24T17:10:15.120+0000] {subprocess.py:106} INFO - [0m17:10:15  2 of 4 START test source_not_null_public_premier_league_2425_raw_away_team ..... [RUN]
[2025-03-24T17:10:15.122+0000] {subprocess.py:106} INFO - [0m17:10:15  CANCEL query test.premier_league_dbt.source_custom_score_format_public_premier_league_2425_raw_.66e0a8d758  [[31mCANCEL[0m]
[2025-03-24T17:10:15.143+0000] {subprocess.py:106} INFO - [0m17:10:15  2 of 4 PASS source_not_null_public_premier_league_2425_raw_away_team ........... [[32mPASS[0m in 0.02s]
[2025-03-24T17:10:15.144+0000] {subprocess.py:106} INFO - [0m17:10:15
[2025-03-24T17:10:15.144+0000] {subprocess.py:106} INFO - [0m17:10:15    Database Error in test source_custom_score_format_public_premier_league_2425_raw_ (models/staging/schema.yml)
[2025-03-24T17:10:15.144+0000] {subprocess.py:106} INFO -   syntax error at or near "not"
[2025-03-24T17:10:15.144+0000] {subprocess.py:106} INFO -   LINE 11: where  is not null
[2025-03-24T17:10:15.145+0000] {subprocess.py:106} INFO -                      ^
[2025-03-24T17:10:15.145+0000] {subprocess.py:106} INFO -   compiled code at target/run/premier_league_dbt/models/staging/schema.yml/source_custom_score_format_public_premier_league_2425_raw_.sql
[2025-03-24T17:10:15.153+0000] {subprocess.py:106} INFO - [0m17:10:15
[2025-03-24T17:10:15.153+0000] {subprocess.py:106} INFO - [0m17:10:15  Finished running 4 data tests in 0 hours 0 minutes and 0.16 seconds (0.16s).
[2025-03-24T17:10:15.178+0000] {subprocess.py:106} INFO - [0m17:10:15
[2025-03-24T17:10:15.178+0000] {subprocess.py:106} INFO - [0m17:10:15  [31mCompleted with 4 errors, 0 partial successes, and 0 warnings:[0m
[2025-03-24T17:10:15.179+0000] {subprocess.py:106} INFO - [0m17:10:15
[2025-03-24T17:10:15.179+0000] {subprocess.py:106} INFO - [0m17:10:15    Database Error in test source_custom_score_format_public_premier_league_2425_raw_ (models/staging/schema.yml)
[2025-03-24T17:10:15.179+0000] {subprocess.py:106} INFO -   syntax error at or near "not"
[2025-03-24T17:10:15.179+0000] {subprocess.py:106} INFO -   LINE 11: where  is not null
[2025-03-24T17:10:15.179+0000] {subprocess.py:106} INFO -                      ^
[2025-03-24T17:10:15.179+0000] {subprocess.py:106} INFO -   compiled code at target/run/premier_league_dbt/models/staging/schema.yml/source_custom_score_format_public_premier_league_2425_raw_.sql
[2025-03-24T17:10:15.181+0000] {subprocess.py:106} INFO - [0m17:10:15
[2025-03-24T17:10:15.182+0000] {subprocess.py:106} INFO - [0m17:10:15  Done. PASS=0 WARN=0 ERROR=1 SKIP=3 TOTAL=4
[2025-03-24T17:10:16.385+0000] {subprocess.py:110} INFO - Command exited with return code 1
[2025-03-24T17:10:16.391+0000] {taskinstance.py:3313} ERROR - Task failed with exception
Traceback (most recent call last):
  File "/home/airflow/.local/lib/python3.12/site-packages/airflow/models/taskinstance.py", line 768, in _execute_task
    result = _execute_callable(context=context, **execute_callable_kwargs)
             ^^^^^^^^^^^^^^^^^^^^^^^^^^^^^^^^^^^^^^^^^^^^^^^^^^^^^^^^^^^^^
  File "/home/airflow/.local/lib/python3.12/site-packages/airflow/models/taskinstance.py", line 734, in _execute_callable
    return ExecutionCallableRunner(
           ^^^^^^^^^^^^^^^^^^^^^^^^
  File "/home/airflow/.local/lib/python3.12/site-packages/airflow/utils/operator_helpers.py", line 252, in run
    return self.func(*args, **kwargs)
           ^^^^^^^^^^^^^^^^^^^^^^^^^^
  File "/home/airflow/.local/lib/python3.12/site-packages/airflow/models/baseoperator.py", line 424, in wrapper
    return func(self, *args, **kwargs)
           ^^^^^^^^^^^^^^^^^^^^^^^^^^^
  File "/home/airflow/.local/lib/python3.12/site-packages/airflow/operators/bash.py", line 276, in execute
    raise AirflowException(
airflow.exceptions.AirflowException: Bash command failed. The command returned a non-zero exit code 1.
[2025-03-24T17:10:16.392+0000] {taskinstance.py:1226} INFO - Marking task as FAILED. dag_id=e2e_data_pipeline, task_id=dbt_execute, run_id=manual__2025-03-24T16:17:51.573790+00:00, execution_date=20250324T161751, start_date=20250324T171013, end_date=20250324T171016
[2025-03-24T17:10:16.402+0000] {taskinstance.py:341} INFO - ::group::Post task execution logs
[2025-03-24T17:10:16.402+0000] {standard_task_runner.py:124} ERROR - Failed to execute job 24 for task dbt_execute (Bash command failed. The command returned a non-zero exit code 1.; 829)
Traceback (most recent call last):
  File "/home/airflow/.local/lib/python3.12/site-packages/airflow/task/task_runner/standard_task_runner.py", line 117, in _start_by_fork
    ret = args.func(args, dag=self.dag)
          ^^^^^^^^^^^^^^^^^^^^^^^^^^^^^
  File "/home/airflow/.local/lib/python3.12/site-packages/airflow/cli/cli_config.py", line 49, in command
    return func(*args, **kwargs)
           ^^^^^^^^^^^^^^^^^^^^^
  File "/home/airflow/.local/lib/python3.12/site-packages/airflow/utils/cli.py", line 116, in wrapper
    return f(*args, **kwargs)
           ^^^^^^^^^^^^^^^^^^
  File "/home/airflow/.local/lib/python3.12/site-packages/airflow/cli/commands/task_command.py", line 483, in task_run
    task_return_code = _run_task_by_selected_method(args, _dag, ti)
                       ^^^^^^^^^^^^^^^^^^^^^^^^^^^^^^^^^^^^^^^^^^^^
  File "/home/airflow/.local/lib/python3.12/site-packages/airflow/cli/commands/task_command.py", line 256, in _run_task_by_selected_method
    return _run_raw_task(args, ti)
           ^^^^^^^^^^^^^^^^^^^^^^^
  File "/home/airflow/.local/lib/python3.12/site-packages/airflow/cli/commands/task_command.py", line 341, in _run_raw_task
    return ti._run_raw_task(
           ^^^^^^^^^^^^^^^^^
  File "/home/airflow/.local/lib/python3.12/site-packages/airflow/utils/session.py", line 97, in wrapper
    return func(*args, session=session, **kwargs)
           ^^^^^^^^^^^^^^^^^^^^^^^^^^^^^^^^^^^^^^
  File "/home/airflow/.local/lib/python3.12/site-packages/airflow/models/taskinstance.py", line 3006, in _run_raw_task
    return _run_raw_task(
           ^^^^^^^^^^^^^^
  File "/home/airflow/.local/lib/python3.12/site-packages/airflow/models/taskinstance.py", line 274, in _run_raw_task
    TaskInstance._execute_task_with_callbacks(
  File "/home/airflow/.local/lib/python3.12/site-packages/airflow/models/taskinstance.py", line 3161, in _execute_task_with_callbacks
    result = self._execute_task(context, task_orig)
             ^^^^^^^^^^^^^^^^^^^^^^^^^^^^^^^^^^^^^^
  File "/home/airflow/.local/lib/python3.12/site-packages/airflow/models/taskinstance.py", line 3185, in _execute_task
    return _execute_task(self, context, task_orig)
           ^^^^^^^^^^^^^^^^^^^^^^^^^^^^^^^^^^^^^^^
  File "/home/airflow/.local/lib/python3.12/site-packages/airflow/models/taskinstance.py", line 768, in _execute_task
    result = _execute_callable(context=context, **execute_callable_kwargs)
             ^^^^^^^^^^^^^^^^^^^^^^^^^^^^^^^^^^^^^^^^^^^^^^^^^^^^^^^^^^^^^
  File "/home/airflow/.local/lib/python3.12/site-packages/airflow/models/taskinstance.py", line 734, in _execute_callable
    return ExecutionCallableRunner(
           ^^^^^^^^^^^^^^^^^^^^^^^^
  File "/home/airflow/.local/lib/python3.12/site-packages/airflow/utils/operator_helpers.py", line 252, in run
    return self.func(*args, **kwargs)
           ^^^^^^^^^^^^^^^^^^^^^^^^^^
  File "/home/airflow/.local/lib/python3.12/site-packages/airflow/models/baseoperator.py", line 424, in wrapper
    return func(self, *args, **kwargs)
           ^^^^^^^^^^^^^^^^^^^^^^^^^^^
  File "/home/airflow/.local/lib/python3.12/site-packages/airflow/operators/bash.py", line 276, in execute
    raise AirflowException(
airflow.exceptions.AirflowException: Bash command failed. The command returned a non-zero exit code 1.
[2025-03-24T17:10:16.411+0000] {local_task_job_runner.py:266} INFO - Task exited with return code 1
[2025-03-24T17:10:16.417+0000] {taskinstance.py:3901} INFO - 0 downstream tasks scheduled from follow-on schedule check
[2025-03-24T17:10:16.418+0000] {local_task_job_runner.py:245} INFO - ::endgroup::
